<?xml version="1.0" ?>
<!-- Simulation Description Format of CLAM arm
Dave Coleman - davetcoleman@gmail.com
1/2/2013

Documentation:

SDF
http://gazebosim.org/sdf/1.2.html
// http://gazebosim.org/sdf/1.3.html

-->
<gazebo version="1.2">
  <model name="clam_arm">
    <static>0</static>



    <!--
        <plugin name="actuator_array_controller" filename="libgazebo_ros_actuator_array.so">
        <alwaysOn>true</alwaysOn>
        <updateRate>50.0</updateRate>
        <robotParam>robot_description</robotParam>
        <joint>
        <name>shoulder_pan_joint</name>
        <home>0.0</home>
        <p>10.0</p>
        <i>0.0</i>
        <d>0.0</d>
        <iClamp>0.0</iClamp>
        </joint>
        <joint>
        <name>joint2</name>
        <home>2.094395102</home>
        <p>10.0</p>
        <i>0.0</i>
        <d>0.0</d>
        <iClamp>0.0</iClamp>
        </joint>
        <joint>
        <name>joint3</name>
        <home>1.483529864</home>
        <p>10.0</p>
        <i>0.0</i>
        <d>0.0</d>
        <iClamp>0.0</iClamp>
        </joint>
        <joint>
        <name>joint4</name>
        <home>0.0</home>
        <p>10.0</p>
        <i>0.0</i>
        <d>0.0</d>
        <iClamp>0.0</iClamp>
        </joint>
        </plugin>  -->


    <!-- tabletop ||||||||||||||||||||||||||||||||||||||||||||||||| -->


    <joint name="tabletop_joint" type="revolute">
      <parent>world</parent>
      <child>tabletop_link</child>
      <axis>
        <limit>
          <lower>0</lower>
          <upper>0</upper>
        </limit>
        <xyz>0.0 0.0 1</xyz>
      </axis>
    </joint>

    <link name="tabletop_link">
      <self_collide>1</self_collide>
      <gravity>1</gravity>
      <pose>0.0 0.0 0.0 1.570795 0 0</pose>

      <inertial>
        <pose>0.384175 0.3048 0 1.570795 0 0</pose>
        <mass>50</mass>
        <inertia>
          <ixx>1</ixx>
          <iyy>1</iyy>
          <izz>1</izz>
          <ixy>0</ixy>
          <ixz>0</ixz>
          <iyz>0</iyz>
        </inertia>
      </inertial>

      <collision name="tabletop_geom">
        <geometry>
          <mesh>
            <uri>model://clam_arm/stl/tabletop.STL</uri>
          </mesh>
        </geometry>
      </collision>

      <visual name="tabletop_visual">
        <geometry>
          <mesh>
            <uri>model://clam_arm/stl/tabletop.STL</uri>
          </mesh>
        </geometry>
        <material>
          <script><uri>file://media/materials/scripts/gazebo.material</uri><name>Gazebo/White</name></script>
        </material>
      </visual>

    </link>

    <!-- base |||||||||||||||||||||||||||||||||||||||||||||||||  -->

    <joint name="base_joint" type="revolute">
      <parent>tabletop_link</parent>
      <child>base_link</child>
      <axis>
        <limit>
          <lower>0</lower>
          <upper>0</upper>
        </limit>
        <xyz>0.0 0.0 1</xyz>
      </axis>
    </joint>

    <link name="base_link">
      <self_collide>1</self_collide>
      <gravity>1</gravity>
      <pose>0.0 0.0 0.017 1.570795 0.0 -1.570795</pose>

      <inertial>
        <mass>10.0</mass>
        <inertia>
          <ixx>1</ixx>
          <iyy>1</iyy>
          <izz>1</izz>
          <ixy>0</ixy>
          <ixz>0</ixz>
          <iyz>0</iyz>
        </inertia>
      </inertial>

      <collision name="base_geom">
        <geometry>
          <mesh>
            <uri>model://clam_arm/stl/base_link.STL</uri>
            <scale>0.001 0.001 0.001</scale>
          </mesh>
        </geometry>
      </collision>

      <visual name="base_visual">
        <geometry>
          <mesh>
            <uri>model://clam_arm/stl/base_link.STL</uri>
            <scale>0.001 0.001 0.001</scale>
          </mesh>
        </geometry>
        <material>
          <script><uri>file://media/materials/scripts/gazebo.material</uri><name>Gazebo/Grey</name></script>
        </material>
      </visual>

    </link>

    <!-- shoulder_pan ||||||||||||||||||||||||||||||||||||||||||||||||| -->

    <joint name="shoulder_pan_joint" type="revolute">
      <parent>base_link</parent>
      <child>shoulder_pan_link</child>
      <pose>0.0 0.0 0.0 0.0 1.570795 0</pose>
      <axis>
        <limit>
          <lower>-2.61799387799</lower>
          <upper>1.98394848567</upper>
        </limit>
        <xyz>0 0 1</xyz>
        <dynamics>
          <damping>2.000000</damping>
          <friction>1.000000</friction>
        </dynamics>
      </axis>
    </joint>

    <link name="shoulder_pan_link">
      <self_collide>1</self_collide>
      <gravity>1</gravity>
      <pose>0.0 0.0 0.067 1.570795 0.0 0</pose>

      <inertial>
        <mass>0.5</mass>
        <inertia>
          <ixx>1</ixx>
          <iyy>1</iyy>
          <izz>1</izz>
          <ixy>0</ixy>
          <ixz>0</ixz>
          <iyz>0</iyz>
        </inertia>
      </inertial>

      <collision name="shoulder_pan_geom">
        <geometry>
          <mesh>
            <uri>model://clam_arm/stl/shoulder_pan_link.STL</uri>
            <scale>0.001 0.001 0.001</scale>
          </mesh>
        </geometry>
      </collision>

      <visual name="shoulder_pan_visual">
        <geometry>
          <mesh>
            <uri>model://clam_arm/stl/shoulder_pan_link.STL</uri>
            <scale>0.001 0.001 0.001</scale>
          </mesh>
        </geometry>
        <material>
          <!-- Orange -->
          <diffuse>1.0 0.423529411765 0.0392156862745 1.0</diffuse>
          <ambient>1.0 0.423529411765 0.0392156862745 1.0</ambient>
        </material>
      </visual>

    </link>

    <!-- shoulder_pitch ||||||||||||||||||||||||||||||||||||||||||||||||| -->

    <joint name="shoulder_pitch_joint" type="revolute">
      <parent>shoulder_pan_link</parent>
      <child>shoulder_pitch_link</child>
      <pose>0.0 0.0 0.0 0.0 1.570795 0</pose>
      <axis>
        <limit>
          <lower>-1.19962513147</lower>
          <upper>1.89994105047</upper>
        </limit>
        <xyz>1 0 0</xyz>
        <dynamics>
          <damping>2.000000</damping>
          <friction>1.000000</friction>
        </dynamics>
      </axis>
    </joint>

    <link name="shoulder_pitch_link">
      <self_collide>1</self_collide>
      <gravity>1</gravity>
      <pose>-0.002 0 0.107 1.570795 3.14159 1.570795</pose>

      <inertial>
        <mass>1</mass>
        <inertia>
          <ixx>1</ixx>
          <iyy>1</iyy>
          <izz>1</izz>
          <ixy>0</ixy>
          <ixz>0</ixz>
          <iyz>0</iyz>
        </inertia>
      </inertial>

      <collision name="shoulder_pitch_geom">
        <geometry>
          <mesh>
            <uri>model://clam_arm/stl/shoulder_pitch_link.STL</uri>
            <scale>0.001 0.001 0.001</scale>
          </mesh>
        </geometry>
      </collision>

      <visual name="shoulder_pitch_visual">
        <geometry>
          <mesh>
            <uri>model://clam_arm/stl/shoulder_pitch_link.STL</uri>
            <scale>0.001 0.001 0.001</scale>
          </mesh>
        </geometry>
        <material>
          <script><uri>file://media/materials/scripts/gazebo.material</uri><name>Gazebo/Grey</name></script>
        </material>
      </visual>

    </link>

    <!-- elbow_roll ||||||||||||||||||||||||||||||||||||||||||||||||| -->

    <joint name="elbow_roll_joint" type="revolute">
      <parent>shoulder_pitch_link</parent>
      <child>elbow_roll_link</child>
      <pose>0 0 0 3.14159 1.570795 0</pose>
      <axis>
        <limit>
          <lower>-2.61799387799</lower>
          <upper>0.705631162427</upper>
        </limit>
        <xyz>0 0 1</xyz>
        <dynamics>
          <damping>2.000000</damping>
          <friction>1.000000</friction>
        </dynamics>

      </axis>
    </joint>

    <link name="elbow_roll_link">
      <self_collide>1</self_collide>
      <gravity>1</gravity>
      <pose>-0.0016 0 0.2625 -1.570795 0 0</pose>

      <inertial>
        <mass>0.01</mass>
        <inertia>
          <ixx>1</ixx>
          <iyy>1</iyy>
          <izz>1</izz>
          <ixy>0</ixy>
          <ixz>0</ixz>
          <iyz>0</iyz>
        </inertia>
      </inertial>

      <collision name="elbow_roll_geom">
        <geometry>
          <mesh>
            <uri>model://clam_arm/stl/elbow_roll_link.STL</uri>
            <scale>0.001 0.001 0.001</scale>
          </mesh>
        </geometry>
      </collision>

      <visual name="elbow_roll_visual">
        <geometry>
          <mesh>
            <uri>model://clam_arm/stl/elbow_roll_link.STL</uri>
            <scale>0.001 0.001 0.001</scale>
          </mesh>
        </geometry>
        <material>
          <!-- Orange -->
          <diffuse>1.0 0.423529411765 0.0392156862745 1.0</diffuse>
          <ambient>1.0 0.423529411765 0.0392156862745 1.0</ambient>
        </material>
      </visual>

    </link>


    <!-- elbow_pitch ||||||||||||||||||||||||||||||||||||||||||||||||| -->

    <joint name="elbow_pitch_joint" type="revolute">
      <parent>elbow_roll_link</parent>
      <child>elbow_pitch_link</child>
      <pose>0 0 0 0.055 1.570795 0</pose>
      <axis>
        <limit>
          <lower>-1.5953400194</lower>
          <upper>1.93281579274</upper>
        </limit>
        <xyz>1 0 0</xyz>
        <dynamics>
          <damping>2.000000</damping>
          <friction>1.000000</friction>
        </dynamics>

      </axis>
    </joint>

    <link name="elbow_pitch_link">
      <self_collide>1</self_collide>
      <gravity>1</gravity>
      <pose>0 0 0.262 1.570795 -3.1416 -1.570795</pose>

      <inertial>
        <mass>2</mass>
        <inertia>
          <ixx>1</ixx>
          <iyy>1</iyy>
          <izz>1</izz>
          <ixy>0</ixy>
          <ixz>0</ixz>
          <iyz>0</iyz>
        </inertia>
      </inertial>

      <collision name="elbow_pitch_geom">
        <geometry>
          <mesh>
            <uri>model://clam_arm/stl/elbow_pitch_link.STL</uri>
            <scale>0.001 0.001 0.001</scale>
          </mesh>
        </geometry>
      </collision>

      <visual name="elbow_pitch_visual">
        <geometry>
          <mesh>
            <uri>model://clam_arm/stl/elbow_pitch_link.STL</uri>
            <scale>0.001 0.001 0.001</scale>
          </mesh>
        </geometry>
        <material>
          <script><uri>file://media/materials/scripts/gazebo.material</uri><name>Gazebo/Grey</name></script>
        </material>
      </visual>

    </link>

    <!-- wrist_roll ||||||||||||||||||||||||||||||||||||||||||||||||| -->

    <joint name="wrist_roll_joint" type="revolute">
      <parent>elbow_pitch_link</parent>
      <child>wrist_roll_link</child>
      <pose>0 0 0 0 1.570795 3.14159</pose>
      <axis>
        <limit>
          <lower>-2.61799387799</lower>
          <upper>2.6128806087</upper>
        </limit>
        <xyz>0 0 1</xyz>
        <dynamics>
          <damping>2.000000</damping>
          <friction>1.000000</friction>
        </dynamics>

      </axis>
    </joint>

    <link name="wrist_roll_link">
      <self_collide>1</self_collide>
      <gravity>1</gravity>
      <pose> 0.0 -0.008 0.5102 -1.570795  0 0 </pose>

      <inertial>
        <mass>0.1</mass>
        <inertia>
          <ixx>1</ixx>
          <iyy>1</iyy>
          <izz>1</izz>
          <ixy>0</ixy>
          <ixz>0</ixz>
          <iyz>0</iyz>
        </inertia>
      </inertial>

      <collision name="wrist_roll_geom">
        <geometry>
          <mesh>
            <uri>model://clam_arm/stl/wrist_roll_link.STL</uri>
            <scale>0.001 0.001 0.001</scale>
          </mesh>
        </geometry>
      </collision>

      <visual name="wrist_roll_visual">
        <geometry>
          <mesh>
            <uri>model://clam_arm/stl/wrist_roll_link.STL</uri>
            <scale>0.001 0.001 0.001</scale>
          </mesh>
        </geometry>
        <material>
          <!-- Orange -->
          <diffuse>1.0 0.423529411765 0.0392156862745 1.0</diffuse>
          <ambient>1.0 0.423529411765 0.0392156862745 1.0</ambient>
        </material>
      </visual>

    </link>

    <plugin name="animate_joints" filename="libanimate_joints.so"/>

  </model>
</gazebo>


