<?xml version="1.0" ?>
<!-- =================================================================================== -->
<!-- |    This document was autogenerated by xacro from clam.xacro                     | -->
<!-- |    EDITING THIS FILE BY HAND IS NOT RECOMMENDED                                 | -->
<!-- =================================================================================== -->
<!-- Robot Description format of CLAM arm 
Dave Coleman - davetcoleman@gmail.com
1/10/2012

Documentation:

URDF
http://www.ros.org/wiki/urdf/XML

Joint Safety Limits
http://www.ros.org/wiki/pr2_controller_manager/safety_limits

XARCO - Macro Language
http://www.ros.org/wiki/xacro

-->
<robot name="clam" xmlns:controller="http://playerstage.sourceforge.net/gazebo/xmlschema/#controller" xmlns:interface="http://playerstage.sourceforge.net/gazebo/xmlschema/#interface" xmlns:sensor="http://playerstage.sourceforge.net/gazebo/xmlschema/#sensor">
  <!-- Include materials -->
  <material name="Black">
    <color rgba="0.0 0.0 0.0 1.0"/>
  </material>
  <material name="Blue">
    <color rgba="0.0 0.0 0.8 1.0"/>
  </material>
  <material name="Green">
    <color rgba="0.0 0.8 0.0 1.0"/>
  </material>
  <material name="Grey">
    <color rgba="0.2 0.2 0.2 1.0"/>
  </material>
  <material name="Orange">
    <color rgba="1.0 0.423529411765 0.0392156862745 1.0"/>
  </material>
  <material name="Brown">
    <color rgba="0.870588235294 0.811764705882 0.764705882353 1.0"/>
  </material>
  <material name="Red">
    <color rgba="0.8 0.0 0.0 1.0"/>
  </material>
  <material name="White">
    <color rgba="1.0 1.0 1.0 1.0"/>
  </material>
  <material name="GunMetalBrushedAluminum">
    <texture filename="package://clam_description/media/gun_metal_brushed_aluminum.jpg"/>
  </material>
  <!-- Constants -->
  <!-- BASE LINK -->
  <link name="base_link">
    <visual>
      <origin rpy="1.570795 0 0" xyz="0 0 0"/>
      <!-- rotate PI/2 -->
      <geometry>
        <mesh filename="package://clam_description/stl/base_link.STL" scale="0.001 0.001 0.001"/>
      </geometry>
      <material name="Grey"/>
    </visual>
    <collision>
      <origin rpy="1.570795 0 0" xyz="0 0 0"/>
      <!-- rotate PI/2 -->
      <geometry>
        <mesh filename="package://clam_description/stl/base_link_simple.STL" scale="0.001 0.001 0.001"/>
      </geometry>
    </collision>
  </link>
  <joint name="shoulder_pan_joint" type="revolute">
    <parent link="base_link"/>
    <child link="shoulder_pan_link"/>
    <origin rpy="0 1.570795 0.0" xyz="0 0 0.05"/>
    <axis xyz="-1 0 0"/>
    <limit effort="300" lower="-2.61799387799" upper="1.98394848567" velocity="1"/>
    <dynamics damping="50" friction="1"/>
  </joint>
  <!-- SHOULDER PAN LINK -->
  <link name="shoulder_pan_link">
    <visual>
      <origin rpy="0 0 1.570795" xyz="0 0 0"/>
      <geometry>
        <mesh filename="package://clam_description/stl/shoulder_pan_link.STL" scale="0.001 0.001 0.001"/>
      </geometry>
      <material name="Orange"/>
    </visual>
    <collision>
      <origin rpy="0 0 1.570795" xyz="0 0 0"/>
      <geometry>
        <mesh filename="package://clam_description/stl/shoulder_pan_link_simple.STL" scale="0.001 0.001 0.001"/>
      </geometry>
    </collision>
  </link>
  <joint name="shoulder_pitch_joint" type="revolute">
    <parent link="shoulder_pan_link"/>
    <child link="shoulder_pitch_link"/>
    <origin rpy="-1.570795 0 1.570795" xyz="-0.041 0.0021 0.0"/>
    <axis xyz="1 0 0"/>
    <limit effort="300" lower="-1.19962513147" upper="1.89994105047" velocity="1"/>
    <dynamics damping="50" friction="1"/>
  </joint>
  <!-- SHOULDER PITCH LINK -->
  <link name="shoulder_pitch_link">
    <visual>
      <origin rpy="1.570795 3.14159 1.570795" xyz="-0.002 0 -0.000"/>
      <geometry>
        <mesh filename="package://clam_description/stl/shoulder_pitch_link.STL" scale="0.001 0.001 0.001"/>
      </geometry>
      <material name="Grey"/>
    </visual>
    <collision>
      <origin rpy="1.570795 3.14159 1.570795" xyz="-0.002 0 -0.000"/>
      <geometry>
        <mesh filename="package://clam_description/stl/shoulder_pitch_link_simple.STL" scale="0.001 0.001 0.001"/>
      </geometry>
    </collision>
  </link>
  <joint name="elbow_roll_joint" type="revolute">
    <parent link="shoulder_pitch_link"/>
    <child link="elbow_roll_link"/>
    <origin rpy="3.14159 1.570795 0" xyz="-0.002 0 0.1206"/>
    <axis xyz="-1 0 0"/>
    <limit effort="300" lower="-2.61799387799" upper="0.705631162427" velocity="1"/>
    <dynamics damping="50" friction="1"/>
  </joint>
  <!-- ELBOW ROLL LINK -->
  <link name="elbow_roll_link">
    <visual>
      <origin rpy="3.14159 1.570795 1.570795" xyz="-0.035 0.0 0.0"/>
      <geometry>
        <mesh filename="package://clam_description/stl/elbow_roll_link.STL" scale="0.001 0.001 0.001"/>
      </geometry>
      <material name="Black"/>
    </visual>
    <collision>
      <origin rpy="3.14159 1.570795 1.570795" xyz="-0.035 0.0 0.0"/>
      <geometry>
        <mesh filename="package://clam_description/stl/elbow_roll_link_simple.STL" scale="0.001 0.001 0.001"/>
      </geometry>
    </collision>
  </link>
  <joint name="elbow_pitch_joint" type="revolute">
    <parent link="elbow_roll_link"/>
    <child link="elbow_pitch_link"/>
    <origin rpy="0.055 1.570795 0" xyz="-0.035 0 0.0"/>
    <axis xyz="1 0 0"/>
    <limit effort="300" lower="-1.5953400194" upper="1.93281579274" velocity="1"/>
    <dynamics damping="50" friction="1"/>
  </joint>
  <!-- ELBOW PITCH LINK -->
  <link name="elbow_pitch_link">
    <visual>
      <origin rpy="1.570795 0 4.712385" xyz="0.0 0 0"/>
      <geometry>
        <mesh filename="package://clam_description/stl/elbow_pitch_link.STL" scale="0.001 0.001 0.001"/>
      </geometry>
      <material name="Orange"/>
    </visual>
    <collision>
      <origin rpy="1.570795 0 4.712385" xyz="0.0 0 0"/>
      <geometry>
        <mesh filename="package://clam_description/stl/elbow_pitch_link_simple.STL" scale="0.001 0.001 0.001"/>
      </geometry>
    </collision>
  </link>
  <joint name="wrist_roll_joint" type="revolute">
    <parent link="elbow_pitch_link"/>
    <child link="wrist_roll_link"/>
    <origin rpy="0 1.570795 3.14159" xyz="0.0 0.0081 -.248"/>
    <axis xyz="1 0 0"/>
    <limit effort="300" lower="-2.61799387799" upper="2.6128806087" velocity="1"/>
    <dynamics damping="50" friction="1"/>
  </joint>
  <!-- WRIST ROLL LINK -->
  <link name="wrist_roll_link">
    <visual>
      <origin rpy="0 1.570795 1.570795" xyz="0 0 0"/>
      <geometry>
        <mesh filename="package://clam_description/stl/wrist_roll_link.STL" scale="0.001 0.001 0.001"/>
      </geometry>
      <material name="Black"/>
    </visual>
    <collision>
      <origin rpy="0 1.570795 1.570795" xyz="0 0 0"/>
      <geometry>
        <mesh filename="package://clam_description/stl/wrist_roll_link_simple.STL" scale="0.001 0.001 0.001"/>
      </geometry>
    </collision>
  </link>
  <joint name="wrist_pitch_joint" type="revolute">
    <parent link="wrist_roll_link"/>
    <child link="wrist_pitch_link"/>
    <origin rpy="0 1.570795 0" xyz="0.0 0.0 0.0001"/>
    <axis xyz="1 0 0"/>
    <limit effort="300" lower="-1.5953400194" upper="1.98394848567" velocity="1"/>
    <dynamics damping="50" friction="1"/>
  </joint>
  <!-- WRIST PITCH LINK -->
  <link name="wrist_pitch_link">
    <visual>
      <origin rpy="3.14159 -1.570795 0" xyz="0 0 0"/>
      <geometry>
        <mesh filename="package://clam_description/stl/wrist_pitch_link.STL" scale="0.001 0.001 0.001"/>
      </geometry>
      <material name="Grey"/>
    </visual>
    <collision>
      <origin rpy="3.14159 -1.570795 0" xyz="0 0 0"/>
      <geometry>
        <mesh filename="package://clam_description/stl/wrist_pitch_link_simple.STL" scale="0.001 0.001 0.001"/>
      </geometry>
    </collision>
  </link>
  <joint name="gripper_roll_joint" type="revolute">
    <parent link="wrist_pitch_link"/>
    <child link="gripper_roll_link"/>
    <origin rpy="4.712385 -1.570795 0" xyz="0 0 0.080"/>
    <axis xyz="1 0 0"/>
    <limit effort="300" lower="-2.61799387799" upper="2.6128806087" velocity="1"/>
    <dynamics damping="50" friction="1"/>
  </joint>
  <!-- GRIPPER ROLL LINK -->
  <link name="gripper_roll_link">
    <visual>
      <origin rpy="0 0 0" xyz="0 0 0"/>
      <geometry>
        <mesh filename="package://clam_description/stl/gripper_grip_link.STL" scale="1 1 1"/>
      </geometry>
      <material name="Orange"/>
    </visual>
  </link>
  <joint name="l_gripper_aft_joint" type="revolute">
    <parent link="gripper_roll_link"/>
    <child link="l_gripper_aft_link"/>
    <origin rpy="3.2672536 1.570795 0.603534345556" xyz="0.026 .017 0"/>
    <axis xyz="1 0 0"/>
    <limit effort="300" lower="0.0" upper="-0.925023722222" velocity="1"/>
    <dynamics damping="50" friction="1"/>
  </joint>
  <!-- LEFT GRIPPER AFT LINK -->
  <link name="l_gripper_aft_link">
    <visual>
      <origin rpy="0 0 3.14159" xyz="0 0 0"/>
      <geometry>
        <mesh filename="package://clam_description/stl/l_gripper_aft_link.STL" scale="1 1 1"/>
      </geometry>
      <material name="Grey"/>
    </visual>
  </link>
</robot>

